Traceback (most recent call last):
  File "/home/sllmdj05/.pyenv/versions/third/lib/python3.11/site-packages/huggingface_hub/utils/_http.py", line 407, in hf_raise_for_status
    response.raise_for_status()
  File "/home/sllmdj05/.pyenv/versions/third/lib/python3.11/site-packages/requests/models.py", line 1026, in raise_for_status
    raise HTTPError(http_error_msg, response=self)
requests.exceptions.HTTPError: 401 Client Error: Unauthorized for url: https://huggingface.co/google/gemma-3-4b-pt/resolve/main/config.json

The above exception was the direct cause of the following exception:

Traceback (most recent call last):
  File "/home/sllmdj05/.pyenv/versions/third/lib/python3.11/site-packages/transformers/utils/hub.py", line 479, in cached_files
    hf_hub_download(
  File "/home/sllmdj05/.pyenv/versions/third/lib/python3.11/site-packages/huggingface_hub/utils/_validators.py", line 114, in _inner_fn
    return fn(*args, **kwargs)
           ^^^^^^^^^^^^^^^^^^^
  File "/home/sllmdj05/.pyenv/versions/third/lib/python3.11/site-packages/huggingface_hub/file_download.py", line 1010, in hf_hub_download
    return _hf_hub_download_to_cache_dir(
           ^^^^^^^^^^^^^^^^^^^^^^^^^^^^^^
  File "/home/sllmdj05/.pyenv/versions/third/lib/python3.11/site-packages/huggingface_hub/file_download.py", line 1117, in _hf_hub_download_to_cache_dir
    _raise_on_head_call_error(head_call_error, force_download, local_files_only)
  File "/home/sllmdj05/.pyenv/versions/third/lib/python3.11/site-packages/huggingface_hub/file_download.py", line 1658, in _raise_on_head_call_error
    raise head_call_error
  File "/home/sllmdj05/.pyenv/versions/third/lib/python3.11/site-packages/huggingface_hub/file_download.py", line 1546, in _get_metadata_or_catch_error
    metadata = get_hf_file_metadata(
               ^^^^^^^^^^^^^^^^^^^^^
  File "/home/sllmdj05/.pyenv/versions/third/lib/python3.11/site-packages/huggingface_hub/utils/_validators.py", line 114, in _inner_fn
    return fn(*args, **kwargs)
           ^^^^^^^^^^^^^^^^^^^
  File "/home/sllmdj05/.pyenv/versions/third/lib/python3.11/site-packages/huggingface_hub/file_download.py", line 1463, in get_hf_file_metadata
    r = _request_wrapper(
        ^^^^^^^^^^^^^^^^^
  File "/home/sllmdj05/.pyenv/versions/third/lib/python3.11/site-packages/huggingface_hub/file_download.py", line 286, in _request_wrapper
    response = _request_wrapper(
               ^^^^^^^^^^^^^^^^^
  File "/home/sllmdj05/.pyenv/versions/third/lib/python3.11/site-packages/huggingface_hub/file_download.py", line 310, in _request_wrapper
    hf_raise_for_status(response)
  File "/home/sllmdj05/.pyenv/versions/third/lib/python3.11/site-packages/huggingface_hub/utils/_http.py", line 424, in hf_raise_for_status
    raise _format(GatedRepoError, message, response) from e
huggingface_hub.errors.GatedRepoError: 401 Client Error. (Request ID: Root=1-68f7926d-4f40530f7d3801b51cdcdddc;10f5859f-58fa-478d-8102-4600b3120dd1)

Cannot access gated repo for url https://huggingface.co/google/gemma-3-4b-pt/resolve/main/config.json.
Access to model google/gemma-3-4b-pt is restricted. You must have access to it and be authenticated to access it. Please log in.

The above exception was the direct cause of the following exception:

Traceback (most recent call last):
  File "/home/sllmdj05/3rd_project/src/evaluate_model.py", line 170, in <module>
    evaluate_model(
  File "/home/sllmdj05/3rd_project/src/evaluate_model.py", line 52, in evaluate_model
    results = simple_evaluate(
              ^^^^^^^^^^^^^^^^
  File "/home/sllmdj05/.pyenv/versions/third/lib/python3.11/site-packages/lm_eval/utils.py", line 456, in _wrapper
    return fn(*args, **kwargs)
           ^^^^^^^^^^^^^^^^^^^
  File "/home/sllmdj05/.pyenv/versions/third/lib/python3.11/site-packages/lm_eval/evaluator.py", line 245, in simple_evaluate
    lm = lm_eval.api.registry.get_model(model).create_from_arg_string(
         ^^^^^^^^^^^^^^^^^^^^^^^^^^^^^^^^^^^^^^^^^^^^^^^^^^^^^^^^^^^^^
  File "/home/sllmdj05/.pyenv/versions/third/lib/python3.11/site-packages/lm_eval/api/model.py", line 155, in create_from_arg_string
    return cls(**args, **args2)
           ^^^^^^^^^^^^^^^^^^^^
  File "/home/sllmdj05/.pyenv/versions/third/lib/python3.11/site-packages/lm_eval/models/huggingface.py", line 176, in __init__
    self._get_config(
  File "/home/sllmdj05/.pyenv/versions/third/lib/python3.11/site-packages/lm_eval/models/huggingface.py", line 558, in _get_config
    self._config = transformers.AutoConfig.from_pretrained(
                   ^^^^^^^^^^^^^^^^^^^^^^^^^^^^^^^^^^^^^^^^
  File "/home/sllmdj05/.pyenv/versions/third/lib/python3.11/site-packages/transformers/models/auto/configuration_auto.py", line 1332, in from_pretrained
    config_dict, unused_kwargs = PretrainedConfig.get_config_dict(pretrained_model_name_or_path, **kwargs)
                                 ^^^^^^^^^^^^^^^^^^^^^^^^^^^^^^^^^^^^^^^^^^^^^^^^^^^^^^^^^^^^^^^^^^^^^^^^^
  File "/home/sllmdj05/.pyenv/versions/third/lib/python3.11/site-packages/transformers/configuration_utils.py", line 662, in get_config_dict
    config_dict, kwargs = cls._get_config_dict(pretrained_model_name_or_path, **kwargs)
                          ^^^^^^^^^^^^^^^^^^^^^^^^^^^^^^^^^^^^^^^^^^^^^^^^^^^^^^^^^^^^^
  File "/home/sllmdj05/.pyenv/versions/third/lib/python3.11/site-packages/transformers/configuration_utils.py", line 721, in _get_config_dict
    resolved_config_file = cached_file(
                           ^^^^^^^^^^^^
  File "/home/sllmdj05/.pyenv/versions/third/lib/python3.11/site-packages/transformers/utils/hub.py", line 322, in cached_file
    file = cached_files(path_or_repo_id=path_or_repo_id, filenames=[filename], **kwargs)
           ^^^^^^^^^^^^^^^^^^^^^^^^^^^^^^^^^^^^^^^^^^^^^^^^^^^^^^^^^^^^^^^^^^^^^^^^^^^^^
  File "/home/sllmdj05/.pyenv/versions/third/lib/python3.11/site-packages/transformers/utils/hub.py", line 543, in cached_files
    raise OSError(
OSError: You are trying to access a gated repo.
Make sure to have access to it at https://huggingface.co/google/gemma-3-4b-pt.
401 Client Error. (Request ID: Root=1-68f7926d-4f40530f7d3801b51cdcdddc;10f5859f-58fa-478d-8102-4600b3120dd1)

Cannot access gated repo for url https://huggingface.co/google/gemma-3-4b-pt/resolve/main/config.json.
Access to model google/gemma-3-4b-pt is restricted. You must have access to it and be authenticated to access it. Please log in.
